<mujoco model="so_100">
  <compiler angle="radian" meshdir="meshes" autolimits="true" />

  <asset>
    <mesh name="Base" file="Base.STL"/>
    <mesh name="Rotation_Pitch" file="Rotation_Pitch.STL"/>
    <mesh name="Upper_Arm" file="Upper_Arm.STL"/>
    <mesh name="Lower_Arm" file="Lower_Arm.STL"/>
    <mesh name="Wrist_Pitch_Roll" file="Wrist_Pitch_Roll.STL"/>
    <mesh name="Fixed_Jaw" file="Fixed_Jaw.STL"/>
    <mesh name="Moving Jaw" file="Moving Jaw.STL"/>
  </asset>

  <worldbody>
    <geom type="mesh" rgba="0.792157 0.819608 0.933333 1" mesh="Base"/>
    <body name="Rotation_Pitch" pos="0 -0.0452 0.0165" quat="0.707105 0.707108 0 0">
      <inertial pos="-9.07886e-05 0.0590972 0.031089" quat="0.363978 0.441169 -0.623108 0.533504" mass="0.119226" diaginertia="5.94278e-05 5.89975e-05 3.13712e-05"/>
      <joint name="Rotation" pos="0 0 0" axis="0 1 0" range="-1.57 1.57"/>
      <geom type="mesh" rgba="0.792157 0.819608 0.933333 1" mesh="Rotation_Pitch"/>
      <body name="Upper_Arm" pos="0 0.1025 0.0306">
        <inertial pos="-1.72052e-05 0.0701802 0.00310545" quat="0.50104 0.498994 -0.493562 0.50632" mass="0.162409" diaginertia="0.000213312 0.000167164 7.01522e-05"/>
        <joint name="Pitch" pos="0 0 0" axis="1 0 0" range="-1.57 1.57"/>
        <geom type="mesh" rgba="0.792157 0.819608 0.933333 1" mesh="Upper_Arm"/>
        <body name="Lower_Arm" pos="0 0.11257 0.028">
          <inertial pos="-0.00339604 0.00137796 0.0768007" quat="0.701995 0.0787996 0.0645626 0.704859" mass="0.147968" diaginertia="0.000138803 0.000107748 4.84242e-05"/>
          <joint name="Elbow" pos="0 0 0" axis="1 0 0" range="-1.57 1.57"/>
          <geom type="mesh" rgba="0.792157 0.819608 0.933333 1" mesh="Lower_Arm"/>
          <body name="Wrist_Pitch_Roll" pos="0 0.0052 0.1349">
            <inertial pos="-0.00852653 -0.0352279 -2.34622e-05" quat="-0.0522806 0.705235 0.0549524 0.704905" mass="0.0661321" diaginertia="3.45403e-05 2.39041e-05 1.94704e-05"/>
            <joint name="Wrist_Pitch" pos="0 0 0" axis="1 0 0" range="-3.14 0"/>
            <geom type="mesh" rgba="0.792157 0.819608 0.933333 1" mesh="Wrist_Pitch_Roll"/>
            <body name="Fixed_Jaw" pos="0 -0.0601 0">
              <inertial pos="0.00552377 -0.0280167 0.000483583" quat="0.41836 0.620891 -0.350644 0.562599" mass="0.0929859" diaginertia="5.03136e-05 4.64098e-05 2.72961e-05"/>
              <joint name="Wrist_Roll" pos="0 0 0" axis="0 1 0" range="-1.57 1.57"/>
              <geom type="mesh" rgba="0.792157 0.819608 0.933333 1" mesh="Fixed_Jaw"/>
              <body name="Moving Jaw" pos="-0.0202 -0.0244 0" quat="1.34924e-11 -3.67321e-06 1 -3.67321e-06">
                <inertial pos="-0.00161745 -0.0303473 0.000449646" quat="0.696562 0.716737 -0.0239844 -0.0227026" mass="0.0202444" diaginertia="1.11265e-05 8.99651e-06 2.99548e-06"/>
                <joint name="Jaw" pos="0 0 0" axis="0 0 1" range="0 1.57"/>
                <geom type="mesh" rgba="0.792157 0.819608 0.933333 1" mesh="Moving Jaw"/>
                <body name="tool0_link" pos="0 0.1 0" quat="-1 1 0 0">
                    <site name="attachment_site" pos="0 0 0" quat="1 0 0 0"/>
                    <site name="eef_site" pos="0 0 0.05" quat="0 0.7071068 -0.7071068 0"/>
                  </body>
              </body>
            </body>
          </body>
        </body>
      </body>
    </body>
  </worldbody>
</mujoco>
